Workbook

Sheet Sheet1
A1: #猴子
A2: #define | B2: cs | D2: cs | E2: cs | F2: cs | G2: s | H2: c | I2: cs | J2: cs | K2: cs | L2: c | M2: cs | N2: c | O2: cs | P2: cs | Q2: c | R2: c | S2: c | T2: c | U2: c
A3: #name | B3: Id | D3: TitleType | E3: TaskType | F3: TaskEvent | G3: SeasonClear | H3: JumpUI | I3: TaskConditionParams | J3: TaskConditionTypes | K3: TaskValueParam | L3: Day | M3: TaskScoreAward | N3: IconType | O3: TaskAward | P3: TaskTreasureChestAward | Q3: TaskDesc | R3: Title | S3: Quality | T3: Icon | U3: Url
A4: #type | B4: index#int | D4: int | E4: int | F4: int | G4: int | H4: int | I4: int[] | J4: int[] | K4: int | L4: int | M4: int | N4: int | O4: int[] | P4: int[] | Q4: string | R4: string | S4: int | T4: string | U4: string
A5: #备注 | C5: 备注 | E5: 任务类型 | F5: 任务事件 | G5: 赛季清理 | H5: 跳转界面 | I5: 任务条件参数数组 | J5: 任务条件判定类型 | L5: 天数 | O5: 任务奖励 | S5: 品质 | T5: 图标地址 | U5: 跳转地址
B6: 10101 | C6: 登录kartparty | D6: 1 | E6: 1 | F6: 102 | G6: 0 | H6: 0 | J6: 0 | K6: 1 | M6: 0 | N6: 0 | O6: =VLOOKUP(B6,Sheet2!A:G,7,0) -> {2,50} | P6: {} | Q6: Login to kartparty | S6: 2 | T6: Assets/Res/Sprites/Items/icon_renwu_denglu.png
B7: 10102 | C7: 购买任意礼包 | D7: 1 | E7: 1 | F7: 103 | G7: 0 | H7: 5 | J7: 0 | K7: 1 | M7: 0 | N7: 0 | O7: =VLOOKUP(B7,Sheet2!A:G,7,0) -> {2,400} | P7: {} | Q7: Daily purchase | S7: 3 | T7: Assets/Res/Sprites/Items/icon_renwu_libao.png
A8: # | B8: 10103 | C8: 每日邀请 | D8: 1 | E8: 1 | F8: 113 | G8: 0 | H8: 9 | J8: 0 | K8: 1 | M8: 0 | N8: 0 | O8: =VLOOKUP(B8,Sheet2!A:G,7,0) -> {2,100} | P8: {} | Q8: Daily invite | S8: 1 | T8: Assets/Res/Sprites/Items/icon_renwu_yaoqing.png
B9: 10104 | C9: 完成5次比赛 | D9: 1 | E9: 1 | F9: 1 | G9: 0 | H9: 1 | J9: 0 | K9: 5 | M9: 0 | N9: 0 | O9: =VLOOKUP(B9,Sheet2!A:G,7,0) -> {2,100} | P9: {} | Q9: Complete 5 matches ({0}) | S9: 3 | T9: Assets/Res/Sprites/Items/icon_renwu_wanchengbisai.png
B10: 10105 | C10: 获得宝箱奖励 | D10: 1 | E10: 1 | F10: 116 | G10: 0 | H10: 3 | J10: 0 | K10: 1 | M10: 0 | N10: 0 | O10: =VLOOKUP(B10,Sheet2!A:G,7,0) -> {2,100} | P10: {} | Q10: Earn chest rewards | S10: 3 | T10: Assets/Res/Sprites/Items/icon_renwu_baoxiang.png
B11: 10106 | C11: 升级任意卡丁车部件 | D11: 1 | E11: 1 | F11: 125 | G11: 0 | H11: 12 | J11: 0 | K11: 1 | M11: 0 | N11: 0 | O11: =VLOOKUP(B11,Sheet2!A:G,7,0) -> {2,200} | P11: {} | Q11: Upgrade Any Kart Part | S11: 3 | T11: Assets/Res/Sprites/Items/icon_renwu_saicheshengji.png
B12: 10107 | C12: 参与匹配玩法 | D12: 1 | E12: 1 | F12: 123 | G12: 0 | H12: 11 | J12: 0 | K12: 1 | M12: 0 | N12: 0 | O12: =VLOOKUP(B12,Sheet2!A:G,7,0) -> {2,30} | P12: {} | Q12: Complete 1 Matching Mode | S12: 1 | T12: Assets/Res/Sprites/Items/icon_renwu_pipei.png
B13: 10201 | C13: Follow on twitter(X)（关注kp官推） | D13: 2 | E13: 2 | F13: 108 | G13: 0 | H13: 7 | J13: 0 | K13: 1 | M13: 0 | N13: 0 | O13: =VLOOKUP(B13,Sheet2!A:G,7,0) -> {2,300} | P13: {} | Q13: Follow on twitter(X) | S13: 1 | T13: Assets/Res/Sprites/Items/icon_renwu_x.png | V13: https://x.com/KaKarbom
B14: 10202 | C14: 关注ceo（warren的推特） | D14: 2 | E14: 2 | F14: 107 | G14: 0 | H14: 8 | J14: 0 | K14: 1 | M14: 0 | N14: 0 | O14: =VLOOKUP(B14,Sheet2!A:G,7,0) -> {2,300} | P14: {} | Q14: Follow @ ceo(X) | S14: 2 | T14: Assets/Res/Sprites/Items/icon_renwu_x.png | V14: https://x.com/Warren0gamer
B15: 10204 | C15: 参与匹配玩法10 | D15: 2 | E15: 2 | F15: 123 | G15: 0 | H15: 11 | J15: 0 | K15: 10 | M15: 0 | N15: 0 | O15: =VLOOKUP(B15,Sheet2!A:G,7,0) -> {2,30} | P15: {} | Q15: Complete 10 Matching Mode ({0}) | S15: 1 | T15: Assets/Res/Sprites/Items/icon_renwu_pipei.png
A16: # | B16: 10205 | C16: OKX Wallet Check in | D16: 2 | E16: 2 | F16: 121 | G16: 0 | H16: 6 | J16: 0 | K16: 1 | M16: 0 | N16: 0 | O16: =VLOOKUP(B16,Sheet2!A:G,7,0) -> {2,60} | P16: {} | Q16: OKX Wallet Check in | S16: 1 | T16: Assets/Res/Sprites/Items/icon_renwu_OKX.png
A17: # | B17: 10301 | C17: 加入寿司玩法 | D17: 14 | E17: 2 | F17: 118 | G17: 0 | H17: 0 | I17: 1 | J17: 0 | K17: 1 | M17: 0 | N17: 0 | O17: =VLOOKUP(B17,Sheet2!A:G,7,0) -> {2,35} | P17: {} | Q17: Play Tonshi | S17: 1 | T17: Assets/Res/Sprites/Items/icon_renwu_shousi.png | U17: https://t.me/OfficialTonshi_bot
A18: # | B18: 10302 | C18: 玩outa | D18: 14 | E18: 2 | F18: 118 | G18: 0 | H18: 0 | I18: 3 | J18: 0 | K18: 1 | M18: 0 | N18: 0 | O18: =VLOOKUP(B18,Sheet2!A:G,7,0) -> {2,35} | P18: {} | Q18: Play OUTA Game | S18: 1 | T18: Assets/Res/Sprites/Items/icon_renwu_auto.png | U18: https://t.me/OUTAxyz_Bot
A19: # | B19: 10303 | C19: 加入outa channel | D19: 14 | E19: 2 | F19: 118 | G19: 0 | H19: 0 | I19: 4 | J19: 0 | K19: 1 | M19: 0 | N19: 0 | O19: =VLOOKUP(B19,Sheet2!A:G,7,0) -> {2,35} | P19: {} | Q19: Follow OUTA Channel | S19: 1 | T19: Assets/Res/Sprites/Items/icon_renwu_auto.png | U19: https://t.me/outa_announcement
A20: # | B20: 10304 | C20: Start Bitbot | D20: 14 | E20: 2 | F20: 118 | G20: 0 | H20: 0 | I20: 5 | J20: 0 | K20: 1 | M20: 0 | N20: 0 | O20: =VLOOKUP(B20,Sheet2!A:G,7,0) -> {2,35} | P20: {} | Q20: Play BitBot Game | S20: 1 | T20: Assets/Res/Sprites/Items/icon_renwu_Bitbot.png | U20: https://t.me/Hello_Bitbot/bitbot?startapp=utm_S2FydHBhcnR5ZEdWa1gx
A21: # | B21: 10305 | C21: UQUID | D21: 14 | E21: 2 | F21: 118 | G21: 0 | H21: 0 | I21: 6 | J21: 0 | K21: 1 | M21: 0 | N21: 0 | O21: =VLOOKUP(B21,Sheet2!A:G,7,0) -> {2,35} | P21: {} | Q21: Join Uquid Chat | S21: 1 | T21: Assets/Res/Sprites/Items/icon_renwu_UQUID.png | U21: https://t.me/uquidcoinofficial
A22: # | B22: 10306 | C22: Follow Uquid X | D22: 14 | E22: 2 | F22: 118 | G22: 0 | H22: 0 | I22: 7 | J22: 0 | K22: 1 | M22: 0 | N22: 0 | O22: =VLOOKUP(B22,Sheet2!A:G,7,0) -> {2,35} | P22: {} | Q22: Follow Uquid X | S22: 1 | T22: Assets/Res/Sprites/Items/icon_renwu_UQUID.png | U22: https://x.com/uquidcard
A23: # | B23: 10307 | C23: HUANGARX BOT | D23: 14 | E23: 2 | F23: 118 | G23: 0 | H23: 0 | I23: 8 | J23: 0 | K23: 1 | M23: 0 | N23: 0 | O23: =VLOOKUP(B23,Sheet2!A:G,7,0) -> {2,35} | P23: {} | Q23: Join HangarX Channel | S23: 1 | T23: Assets/Res/Sprites/Items/icon_renwu_HUANGARX.png | U23: https://t.me/hangarxgam
A24: # | B24: 10308 | C24: 加入HUANGARX channel | D24: 14 | E24: 2 | F24: 118 | G24: 0 | H24: 0 | I24: 9 | J24: 0 | K24: 1 | M24: 0 | N24: 0 | O24: =VLOOKUP(B24,Sheet2!A:G,7,0) -> {2,35} | P24: {} | Q24: Follow HangarX X | S24: 1 | T24: Assets/Res/Sprites/Items/icon_renwu_HUANGARX.png | U24: https://x.com/Hangarxio
A25: # | B25: 10309 | C25: Play BAYCMINER! | D25: 14 | E25: 2 | F25: 118 | G25: 0 | H25: 0 | I25: 10 | J25: 0 | K25: 1 | M25: 0 | N25: 0 | O25: =VLOOKUP(B25,Sheet2!A:G,7,0) -> {2,35} | P25: {} | Q25: Play BAYCMiner Game | S25: 1 | T25: Assets/Res/Sprites/Items/icon_renwu_BAYCMINER.png | U25: https://t.me/BtokMinerBot?profile
A26: # | B26: 10310 | C26: Join BAYCMINER channel | D26: 14 | E26: 2 | F26: 118 | G26: 0 | H26: 0 | I26: 11 | J26: 0 | K26: 1 | M26: 0 | N26: 0 | O26: =VLOOKUP(B26,Sheet2!A:G,7,0) -> {2,35} | P26: {} | Q26: Follow BAYCMiner Channel | S26: 1 | T26: Assets/Res/Sprites/Items/icon_renwu_BAYCMINER.png | U26: https://t.me/baycminerchannel
A27: # | B27: 10311 | C27: UTXORD | D27: 14 | E27: 2 | F27: 118 | G27: 0 | H27: 0 | I27: 12 | J27: 0 | K27: 1 | M27: 0 | N27: 0 | O27: =VLOOKUP(B27,Sheet2!A:G,7,0) -> {2,35} | P27: {} | Q27: Follow UTXORD Channel | S27: 1 | T27: Assets/Res/Sprites/Items/icon_renwu_UTXORD.png | U27: https://t.me/UTXORDChannelIsBithoven
A28: # | B28: 10312 | C28: Join Clockie Chaos bot | D28: 14 | E28: 2 | F28: 118 | G28: 0 | H28: 0 | I28: 13 | J28: 0 | K28: 1 | M28: 0 | N28: 0 | O28: =VLOOKUP(B28,Sheet2!A:G,7,0) -> {2,35} | P28: {} | Q28: Play Clockie Chaos Game | S28: 1 | T28: Assets/Res/Sprites/Items/icon_renwu_Clockie.png | U28: https://t.me/ClockieChaosBot
... A68: # | B68: 10353 | C68: Play Qappi Miner | D68: 14 | E68: 2 | F68: 118 | G68: 0 | H68: 0 | I68: 53 | J68: 0 | K68: 1 | M68: 0 | N68: 0 | O68: =VLOOKUP(B68,Sheet2!A:G,7,0) -> {2,35} | P68: {} | Q68: Play Qappi Miner | S68: 1 | T68: Assets/Res/Sprites/Items/icon_renwu_Qappi.png | U68: https://t.me/QappiMinerBot?start=5446349397
A69: # | B69: 10354 | C69: Play NotMushCoin Game | D69: 14 | E69: 2 | F69: 118 | G69: 0 | H69: 0 | I69: 54 | J69: 0 | K69: 1 | M69: 0 | N69: 0 | O69: {2,35} | P69: {} | Q69: Play NotMushCoin Game | S69: 1 | T69: Assets/Res/Sprites/Items/icon_renwu_NotMushCoin.png | U69: https://t.me/NotMushCoin_bot/play?startapp=m_5767015060
A70: # | B70: 10355 | C70: Play BeeVerse Game | D70: 14 | E70: 2 | F70: 118 | G70: 0 | H70: 0 | I70: 55 | J70: 0 | K70: 1 | M70: 0 | N70: 0 | O70: {2,35} | P70: {} | Q70: Play BeeVerse Game | S70: 1 | T70: Assets/Res/Sprites/Items/icon_renwu_BeeVerse.png | U70: https://t.me/bee_verse_bot?start=5446349397
A71: # | B71: 10356 | C71: Play Musgard Game | D71: 14 | E71: 2 | F71: 118 | G71: 0 | H71: 0 | I71: 56 | J71: 0 | K71: 1 | M71: 0 | N71: 0 | O71: {2,35} | P71: {} | Q71: Play Musgard Game | S71: 1 | T71: Assets/Res/Sprites/Items/icon_renwu_musgard.png | U71: https://t.me/musgard_bot?startapp=1731971346
A72: # | B72: 10357 | C72: Play Gshake Game | D72: 14 | E72: 2 | F72: 118 | G72: 0 | H72: 0 | I72: 57 | J72: 0 | K72: 1 | M72: 0 | N72: 0 | O72: {2,35} | P72: {} | Q72: Play Gshake Game | S72: 1 | T72: Assets/Res/Sprites/Items/icon_renwu_gshake.png | U72: https://t.me/gshake_bot/game?startapp=5sY34nd3XS
A73: # | B73: 10358 | C73: Play BlessedI D Game | D73: 14 | E73: 2 | F73: 118 | G73: 0 | H73: 0 | I73: 58 | J73: 0 | K73: 1 | M73: 0 | N73: 0 | O73: {2,35} | P73: {} | Q73: Play BlessedI D Game | S73: 1 | T73: Assets/Res/Sprites/Items/icon_renwu_BlessedID.png | U73: https://t.me/BlessedID_bot?startapp=kartparty
A74: # | B74: 10359 | C74: Play Ackinacki Game | D74: 14 | E74: 2 | F74: 118 | G74: 0 | H74: 0 | I74: 59 | J74: 0 | K74: 1 | M74: 0 | N74: 0 | O74: {2,35} | P74: {} | Q74: Play Ackinacki Game | S74: 1 | T74: Assets/Res/Sprites/Items/icon_renwu_ackinacki.png | U74: https://t.me/ackinacki_bot/ackinacki_app?startapp=eyJyZWZlcnJlciI6IndoMXRlN2V0aCJ9
A75: # | B75: 10360 | C75: Play Retro_Bit Game | D75: 14 | E75: 2 | F75: 118 | G75: 0 | H75: 0 | I75: 60 | J75: 0 | K75: 1 | M75: 0 | N75: 0 | O75: {2,35} | P75: {} | Q75: Play Retro_Bit Game | S75: 1 | T75: Assets/Res/Sprites/Items/icon_renwu_RetroBit.png | U75: https://t.me/Retro_Bit_bot/app?startapp=7163301039
A76: # | B76: 10361 | C76: Play Fandom_mquest Game | D76: 14 | E76: 2 | F76: 118 | G76: 0 | H76: 0 | I76: 61 | J76: 0 | K76: 1 | M76: 0 | N76: 0 | O76: {2,35} | P76: {} | Q76: Play Fandom_mquest Game | S76: 1 | T76: Assets/Res/Sprites/Items/icon_renwu_fandom_mquest.png | U76: https://t.me/fandom_mquest_bot
A77: # | B77: 10362 | C77: Play Tokyo Beast Love Drop Game | D77: 14 | E77: 2 | F77: 118 | G77: 0 | H77: 0 | I77: 62 | J77: 0 | K77: 1 | M77: 0 | N77: 0 | O77: {2,35} | P77: {} | Q77: Play Tokyo Beast Love Drop Game | S77: 1 | T77: Assets/Res/Sprites/Items/icon_renwu_TokyoBeastLoveDrop.png | U77: https://t.me/tokyobeast_lovedrop_bot/lovedrop?startapp=425FO23KHS
A78: # | B78: 10363 | C78: Play Mimiland Game | D78: 14 | E78: 2 | F78: 118 | G78: 0 | H78: 0 | I78: 63 | J78: 0 | K78: 1 | M78: 0 | N78: 0 | O78: {2,35} | P78: {} | Q78: Play Mimiland Game | S78: 1 | T78: Assets/Res/Sprites/Items/icon_renwu_Mimiland.png | U78: https://t.me/Mimiland_appbot/app?startapp=ref_eyJwIjoiIiwiZiI6InJlZiIsInIiOiI1NDQ2MzQ5Mzk3IiwibSI6IjY3M2M1M2FhMThjMmEzNDZjZDcxMmYzZiJ9
A79: # | B79: 10364 | C79: Play Ocean Kombat Game | D79: 14 | E79: 2 | F79: 118 | G79: 0 | H79: 0 | I79: 64 | J79: 0 | K79: 1 | M79: 0 | N79: 0 | O79: {2,35} | P79: {} | Q79: Play Ocean Kombat Game | S79: 1 | T79: Assets/Res/Sprites/Items/icon_renwu_Ocean_kombat.png | U79: https://t.me/ocean_kombat_bot/app?startapp=d306c2a8-e9e0-4357-a147-d604ba427cda
...

Sheet Sheet2
A1: 10205 | B1: OKX Wallet Check in | C1: { | D1: 2 | E1: 60 | F1: } | G1: ="{"&D1&","&E1&"}" -> {2,60}
A2: 10101 | B2: 登录kartparty | C2: { | D2: 2 | E2: 50 | F2: } | G2: ="{"&D2&","&E2&"}" -> {2,50}
A3: 10102 | B3: 购买任意礼包 | C3: { | D3: 2 | E3: 400 | F3: } | G3: ="{"&D3&","&E3&"}" -> {2,400}
A4: 10103 | B4: 每日邀请 | C4: { | D4: 2 | E4: 100 | F4: } | G4: ="{"&D4&","&E4&"}" -> {2,100}
A5: 10104 | B5: 完成5次比赛 | C5: { | D5: 2 | E5: 100 | F5: } | G5: ="{"&D5&","&E5&"}" -> {2,100}
A6: 10105 | B6: 获得宝箱奖励 | C6: { | D6: 2 | E6: 100 | F6: } | G6: ="{"&D6&","&E6&"}" -> {2,100}
A7: 10106 | B7: 升级任意卡丁车部件 | C7: { | D7: 2 | E7: 200 | F7: } | G7: ="{"&D7&","&E7&"}" -> {2,200}
A8: 10107 | B8: 参与匹配玩法 | C8: { | D8: 2 | E8: 30 | F8: } | G8: ="{"&D8&","&E8&"}" -> {2,30}
A9: 10201 | B9: Follow on twitter(X)（关注kp官推） | C9: { | D9: 2 | E9: 300 | F9: } | G9: ="{"&D9&","&E9&"}" -> {2,300}
A10: 10202 | B10: 关注ceo（warren的推特） | C10: { | D10: 2 | E10: 300 | F10: } | G10: ="{"&D10&","&E10&"}" -> {2,300}
A11: 10203 | B11: 加入Kartparty Chat | C11: { | D11: 2 | E11: 30 | F11: } | G11: ="{"&D11&","&E11&"}" -> {2,30}
A12: 10204 | B12: 参与匹配玩法 | C12: { | D12: 2 | E12: 30 | F12: } | G12: ="{"&D12&","&E12&"}" -> {2,30}
... A27: 10315 | B27: Follow popp X | C27: { | D27: 2 | E27: 35 | F27: } | G27: ="{"&D27&","&E27&"}" -> {2,35}
A28: 10316 | C28: { | D28: 2 | E28: 35 | F28: } | G28: ="{"&D28&","&E28&"}" -> {2,35}
A29: 10317 | C29: { | D29: 2 | E29: 35 | F29: } | G29: ="{"&D29&","&E29&"}" -> {2,35}
A30: 10318 | C30: { | D30: 2 | E30: 35 | F30: } | G30: ="{"&D30&","&E30&"}" -> {2,35}
A31: 10319 | C31: { | D31: 2 | E31: 35 | F31: } | G31: ="{"&D31&","&E31&"}" -> {2,35}
A32: 10320 | C32: { | D32: 2 | E32: 35 | F32: } | G32: ="{"&D32&","&E32&"}" -> {2,35}
A33: 10321 | C33: { | D33: 2 | E33: 35 | F33: } | G33: ="{"&D33&","&E33&"}" -> {2,35}
A34: 10322 | C34: { | D34: 2 | E34: 35 | F34: } | G34: ="{"&D34&","&E34&"}" -> {2,35}
A35: 10323 | C35: { | D35: 2 | E35: 35 | F35: } | G35: ="{"&D35&","&E35&"}" -> {2,35}
A36: 10324 | C36: { | D36: 2 | E36: 35 | F36: } | G36: ="{"&D36&","&E36&"}" -> {2,35}
A37: 10325 | C37: { | D37: 2 | E37: 35 | F37: } | G37: ="{"&D37&","&E37&"}" -> {2,35}
A38: 10326 | C38: { | D38: 2 | E38: 35 | F38: } | G38: ="{"&D38&","&E38&"}" -> {2,35}
A39: 10327 | C39: { | D39: 2 | E39: 35 | F39: } | G39: ="{"&D39&","&E39&"}" -> {2,35}
... A113: 10401 | C113: { | D113: 2 | E113: 35 | F113: } | G113: ="{"&D113&","&E113&"}" -> {2,35}
A114: 10401 | B114: 成就累计登录1天 | C114: { | D114: 5 | E114: 210 | F114: } | G114: ="{"&D114&","&E114&"}" -> {5,210}
A115: 10402 | B115: 成就累计登录2天 | C115: { | D115: 5 | E115: 220 | F115: } | G115: ="{"&D115&","&E115&"}" -> {5,220}
A116: 10403 | B116: 成就累计登录3天 | C116: { | D116: 5 | E116: 230 | F116: } | G116: ="{"&D116&","&E116&"}" -> {5,230}
A117: 10408 | B117: 成就累计登录5天 | C117: { | D117: 5 | E117: 240 | F117: } | G117: ="{"&D117&","&E117&"}" -> {5,240}
A118: 10404 | B118: 成就累计登录7天 | C118: { | D118: 5 | E118: 250 | F118: } | G118: ="{"&D118&","&E118&"}" -> {5,250}
A119: 10405 | B119: 成就累计登录10天 | C119: { | D119: 5 | E119: 260 | F119: } | G119: ="{"&D119&","&E119&"}" -> {5,260}
A120: 10406 | B120: 成就累计登录14天 | C120: { | D120: 5 | E120: 270 | F120: } | G120: ="{"&D120&","&E120&"}" -> {5,270}
A121: 10409 | B121: 成就累计登录20天 | C121: { | D121: 5 | E121: 280 | F121: } | G121: ="{"&D121&","&E121&"}" -> {5,280}
A122: 10410 | B122: 成就累计登录25天 | C122: { | D122: 5 | E122: 290 | F122: } | G122: ="{"&D122&","&E122&"}" -> {5,290}
A123: 10407 | B123: 成就累计登录30天 | C123: { | D123: 5 | E123: 300 | F123: } | G123: ="{"&D123&","&E123&"}" -> {5,300}
A124: 10501 | B124: 成就完成首充 | C124: { | D124: 2 | E124: 300 | F124: } | G124: ="{"&D124&","&E124&"}" -> {2,300}
A125: 10502 | B125: 累计充值$10 | C125: { | D125: 2 | E125: 300 | F125: } | G125: ="{"&D125&","&E125&"}" -> {2,300}
... A201: 20014 | B201: 转盘七日任务 每日签到7 | C201: { | D201: 6 | E201: 1 | F201: } | G201: ="{"&D201&","&E201&"}" -> {6,1}
A202: 21000 | B202: 完成一次全部每日任务 | C202: { | F202: } | G202: ="{"&D202&","&E202&"}" -> {,}
